[2025-08-06 10:45:26,000] {taskinstance.py:1159} INFO - Dependencies all met for <TaskInstance: send_weather_to_kafka.run_kafka_consumer_to_logstash scheduled__2025-08-06T08:40:19.877409+00:00 [queued]>
[2025-08-06 10:45:26,020] {taskinstance.py:1159} INFO - Dependencies all met for <TaskInstance: send_weather_to_kafka.run_kafka_consumer_to_logstash scheduled__2025-08-06T08:40:19.877409+00:00 [queued]>
[2025-08-06 10:45:26,020] {taskinstance.py:1356} INFO - 
--------------------------------------------------------------------------------
[2025-08-06 10:45:26,021] {taskinstance.py:1357} INFO - Starting attempt 2 of 2
[2025-08-06 10:45:26,021] {taskinstance.py:1358} INFO - 
--------------------------------------------------------------------------------
[2025-08-06 10:45:26,046] {taskinstance.py:1377} INFO - Executing <Task(BashOperator): run_kafka_consumer_to_logstash> on 2025-08-06 08:40:19.877409+00:00
[2025-08-06 10:45:26,056] {standard_task_runner.py:52} INFO - Started process 22424 to run task
[2025-08-06 10:45:26,061] {standard_task_runner.py:79} INFO - Running: ['***', 'tasks', 'run', 'send_weather_to_kafka', 'run_kafka_consumer_to_logstash', 'scheduled__2025-08-06T08:40:19.877409+00:00', '--job-id', '21', '--raw', '--subdir', 'DAGS_FOLDER/dag_meteo.py', '--cfg-path', '/tmp/tmpb9xnoxsv', '--error-file', '/tmp/tmp_m7a9qk_']
[2025-08-06 10:45:26,063] {standard_task_runner.py:80} INFO - Job 21: Subtask run_kafka_consumer_to_logstash
[2025-08-06 10:45:26,091] {logging_mixin.py:115} WARNING - /home/***/.local/lib/python3.7/site-packages/***/configuration.py:470 DeprecationWarning: The sql_alchemy_conn option in [core] has been moved to the sql_alchemy_conn option in [database] - the old setting has been used, but please update your config.
[2025-08-06 10:45:26,175] {task_command.py:369} INFO - Running <TaskInstance: send_weather_to_kafka.run_kafka_consumer_to_logstash scheduled__2025-08-06T08:40:19.877409+00:00 [running]> on host 536c12e0b7f9
[2025-08-06 10:45:26,313] {taskinstance.py:1571} INFO - Exporting the following env vars:
AIRFLOW_CTX_DAG_OWNER=***
AIRFLOW_CTX_DAG_ID=send_weather_to_kafka
AIRFLOW_CTX_TASK_ID=run_kafka_consumer_to_logstash
AIRFLOW_CTX_EXECUTION_DATE=2025-08-06T08:40:19.877409+00:00
AIRFLOW_CTX_TRY_NUMBER=2
AIRFLOW_CTX_DAG_RUN_ID=scheduled__2025-08-06T08:40:19.877409+00:00
[2025-08-06 10:45:26,314] {subprocess.py:62} INFO - Tmp dir root location: 
 /tmp
[2025-08-06 10:45:26,315] {subprocess.py:74} INFO - Running command: ['bash', '-c', 'cd /opt/***/scripts && python3 elk/logstash/pipeline/logstash.conf']
[2025-08-06 10:45:26,336] {subprocess.py:85} INFO - Output:
[2025-08-06 10:45:26,510] {subprocess.py:92} INFO -   File "elk/logstash/pipeline/logstash.conf", line 1
[2025-08-06 10:45:26,510] {subprocess.py:92} INFO -     input {
[2025-08-06 10:45:26,510] {subprocess.py:92} INFO -           ^
[2025-08-06 10:45:26,511] {subprocess.py:92} INFO - SyntaxError: invalid syntax
[2025-08-06 10:45:26,514] {subprocess.py:96} INFO - Command exited with return code 1
[2025-08-06 10:45:26,542] {taskinstance.py:1889} ERROR - Task failed with exception
Traceback (most recent call last):
  File "/home/airflow/.local/lib/python3.7/site-packages/airflow/operators/bash.py", line 195, in execute
    f'Bash command failed. The command returned a non-zero exit code {result.exit_code}.'
airflow.exceptions.AirflowException: Bash command failed. The command returned a non-zero exit code 1.
[2025-08-06 10:45:26,549] {taskinstance.py:1400} INFO - Marking task as FAILED. dag_id=send_weather_to_kafka, task_id=run_kafka_consumer_to_logstash, execution_date=20250806T084019, start_date=20250806T104526, end_date=20250806T104526
[2025-08-06 10:45:26,571] {standard_task_runner.py:97} ERROR - Failed to execute job 21 for task run_kafka_consumer_to_logstash (Bash command failed. The command returned a non-zero exit code 1.; 22424)
[2025-08-06 10:45:26,593] {local_task_job.py:156} INFO - Task exited with return code 1
[2025-08-06 10:45:26,675] {local_task_job.py:273} INFO - 0 downstream tasks scheduled from follow-on schedule check
