[2025-08-05 22:24:05,240] {taskinstance.py:1159} INFO - Dependencies all met for <TaskInstance: send_weather_to_kafka.run_kafka_consumer_to_redis scheduled__2025-08-05T21:00:00+00:00 [queued]>
[2025-08-05 22:24:05,252] {taskinstance.py:1159} INFO - Dependencies all met for <TaskInstance: send_weather_to_kafka.run_kafka_consumer_to_redis scheduled__2025-08-05T21:00:00+00:00 [queued]>
[2025-08-05 22:24:05,252] {taskinstance.py:1356} INFO - 
--------------------------------------------------------------------------------
[2025-08-05 22:24:05,252] {taskinstance.py:1357} INFO - Starting attempt 1 of 2
[2025-08-05 22:24:05,252] {taskinstance.py:1358} INFO - 
--------------------------------------------------------------------------------
[2025-08-05 22:24:05,270] {taskinstance.py:1377} INFO - Executing <Task(BashOperator): run_kafka_consumer_to_redis> on 2025-08-05 21:00:00+00:00
[2025-08-05 22:24:05,276] {standard_task_runner.py:52} INFO - Started process 20274 to run task
[2025-08-05 22:24:05,279] {standard_task_runner.py:79} INFO - Running: ['***', 'tasks', 'run', 'send_weather_to_kafka', 'run_kafka_consumer_to_redis', 'scheduled__2025-08-05T21:00:00+00:00', '--job-id', '3', '--raw', '--subdir', 'DAGS_FOLDER/dag_meteo.py', '--cfg-path', '/tmp/tmpgpd5v1f5', '--error-file', '/tmp/tmp06fxj03i']
[2025-08-05 22:24:05,280] {standard_task_runner.py:80} INFO - Job 3: Subtask run_kafka_consumer_to_redis
[2025-08-05 22:24:05,301] {logging_mixin.py:115} WARNING - /home/***/.local/lib/python3.7/site-packages/***/configuration.py:470 DeprecationWarning: The sql_alchemy_conn option in [core] has been moved to the sql_alchemy_conn option in [database] - the old setting has been used, but please update your config.
[2025-08-05 22:24:05,351] {task_command.py:369} INFO - Running <TaskInstance: send_weather_to_kafka.run_kafka_consumer_to_redis scheduled__2025-08-05T21:00:00+00:00 [running]> on host 536c12e0b7f9
[2025-08-05 22:24:05,451] {taskinstance.py:1571} INFO - Exporting the following env vars:
AIRFLOW_CTX_DAG_OWNER=***
AIRFLOW_CTX_DAG_ID=send_weather_to_kafka
AIRFLOW_CTX_TASK_ID=run_kafka_consumer_to_redis
AIRFLOW_CTX_EXECUTION_DATE=2025-08-05T21:00:00+00:00
AIRFLOW_CTX_TRY_NUMBER=1
AIRFLOW_CTX_DAG_RUN_ID=scheduled__2025-08-05T21:00:00+00:00
[2025-08-05 22:24:05,451] {subprocess.py:62} INFO - Tmp dir root location: 
 /tmp
[2025-08-05 22:24:05,452] {subprocess.py:74} INFO - Running command: ['bash', '-c', 'cd /opt/***/scripts && python3 kafka/consumer_redis.py']
[2025-08-05 22:24:05,467] {subprocess.py:85} INFO - Output:
[2025-08-05 23:42:30,560] {local_task_job.py:221} WARNING - State of this instance has been externally set to up_for_retry. Terminating instance.
[2025-08-05 23:42:30,564] {process_utils.py:129} INFO - Sending Signals.SIGTERM to group 20274. PIDs of all processes in the group: [20275, 20274]
[2025-08-05 23:42:30,565] {process_utils.py:80} INFO - Sending the signal Signals.SIGTERM to group 20274
[2025-08-05 23:42:30,565] {taskinstance.py:1541} ERROR - Received SIGTERM. Terminating subprocesses.
[2025-08-05 23:42:30,565] {subprocess.py:103} INFO - Sending SIGTERM signal to process group
[2025-08-05 23:42:30,594] {taskinstance.py:1889} ERROR - Task failed with exception
Traceback (most recent call last):
  File "/home/airflow/.local/lib/python3.7/site-packages/airflow/operators/bash.py", line 189, in execute
    cwd=self.cwd,
  File "/home/airflow/.local/lib/python3.7/site-packages/airflow/hooks/subprocess.py", line 90, in run_command
    for raw_line in iter(self.sub_process.stdout.readline, b''):
  File "/home/airflow/.local/lib/python3.7/site-packages/airflow/models/taskinstance.py", line 1543, in signal_handler
    raise AirflowException("Task received SIGTERM signal")
airflow.exceptions.AirflowException: Task received SIGTERM signal
[2025-08-05 23:42:30,603] {taskinstance.py:1400} INFO - Marking task as FAILED. dag_id=send_weather_to_kafka, task_id=run_kafka_consumer_to_redis, execution_date=20250805T210000, start_date=20250805T222405, end_date=20250805T234230
[2025-08-05 23:42:30,626] {standard_task_runner.py:97} ERROR - Failed to execute job 3 for task run_kafka_consumer_to_redis (Task received SIGTERM signal; 20274)
[2025-08-05 23:42:30,658] {process_utils.py:75} INFO - Process psutil.Process(pid=20275, status='terminated', started='22:24:04') (20275) terminated with exit code None
[2025-08-05 23:42:30,658] {process_utils.py:75} INFO - Process psutil.Process(pid=20274, status='terminated', exitcode=1, started='22:24:04') (20274) terminated with exit code 1
