[2025-08-06 09:00:06,841] {taskinstance.py:1159} INFO - Dependencies all met for <TaskInstance: send_weather_to_kafka.run_kafka_consumer_to_redis scheduled__2025-08-06T08:00:00+00:00 [queued]>
[2025-08-06 09:00:06,854] {taskinstance.py:1159} INFO - Dependencies all met for <TaskInstance: send_weather_to_kafka.run_kafka_consumer_to_redis scheduled__2025-08-06T08:00:00+00:00 [queued]>
[2025-08-06 09:00:06,854] {taskinstance.py:1356} INFO - 
--------------------------------------------------------------------------------
[2025-08-06 09:00:06,855] {taskinstance.py:1357} INFO - Starting attempt 1 of 2
[2025-08-06 09:00:06,855] {taskinstance.py:1358} INFO - 
--------------------------------------------------------------------------------
[2025-08-06 09:00:06,875] {taskinstance.py:1377} INFO - Executing <Task(BashOperator): run_kafka_consumer_to_redis> on 2025-08-06 08:00:00+00:00
[2025-08-06 09:00:06,882] {standard_task_runner.py:52} INFO - Started process 21191 to run task
[2025-08-06 09:00:06,886] {standard_task_runner.py:79} INFO - Running: ['***', 'tasks', 'run', 'send_weather_to_kafka', 'run_kafka_consumer_to_redis', 'scheduled__2025-08-06T08:00:00+00:00', '--job-id', '12', '--raw', '--subdir', 'DAGS_FOLDER/dag_meteo.py', '--cfg-path', '/tmp/tmp0phu6w0v', '--error-file', '/tmp/tmpe92ichlv']
[2025-08-06 09:00:06,887] {standard_task_runner.py:80} INFO - Job 12: Subtask run_kafka_consumer_to_redis
[2025-08-06 09:00:06,905] {logging_mixin.py:115} WARNING - /home/***/.local/lib/python3.7/site-packages/***/configuration.py:470 DeprecationWarning: The sql_alchemy_conn option in [core] has been moved to the sql_alchemy_conn option in [database] - the old setting has been used, but please update your config.
[2025-08-06 09:00:06,954] {task_command.py:369} INFO - Running <TaskInstance: send_weather_to_kafka.run_kafka_consumer_to_redis scheduled__2025-08-06T08:00:00+00:00 [running]> on host 536c12e0b7f9
[2025-08-06 09:00:07,057] {taskinstance.py:1571} INFO - Exporting the following env vars:
AIRFLOW_CTX_DAG_OWNER=***
AIRFLOW_CTX_DAG_ID=send_weather_to_kafka
AIRFLOW_CTX_TASK_ID=run_kafka_consumer_to_redis
AIRFLOW_CTX_EXECUTION_DATE=2025-08-06T08:00:00+00:00
AIRFLOW_CTX_TRY_NUMBER=1
AIRFLOW_CTX_DAG_RUN_ID=scheduled__2025-08-06T08:00:00+00:00
[2025-08-06 09:00:07,058] {subprocess.py:62} INFO - Tmp dir root location: 
 /tmp
[2025-08-06 09:00:07,059] {subprocess.py:74} INFO - Running command: ['bash', '-c', 'cd /opt/***/scripts && python3 kafka/consumer_redis.py']
[2025-08-06 09:00:07,076] {subprocess.py:85} INFO - Output:
[2025-08-06 10:40:19,798] {local_task_job.py:221} WARNING - State of this instance has been externally set to removed. Terminating instance.
[2025-08-06 10:40:19,800] {process_utils.py:129} INFO - Sending Signals.SIGTERM to group 21191. PIDs of all processes in the group: [21192, 21191]
[2025-08-06 10:40:19,800] {process_utils.py:80} INFO - Sending the signal Signals.SIGTERM to group 21191
[2025-08-06 10:40:19,801] {taskinstance.py:1541} ERROR - Received SIGTERM. Terminating subprocesses.
[2025-08-06 10:40:19,801] {subprocess.py:103} INFO - Sending SIGTERM signal to process group
[2025-08-06 10:40:19,829] {taskinstance.py:1889} ERROR - Task failed with exception
Traceback (most recent call last):
  File "/home/airflow/.local/lib/python3.7/site-packages/airflow/operators/bash.py", line 189, in execute
    cwd=self.cwd,
  File "/home/airflow/.local/lib/python3.7/site-packages/airflow/hooks/subprocess.py", line 90, in run_command
    for raw_line in iter(self.sub_process.stdout.readline, b''):
  File "/home/airflow/.local/lib/python3.7/site-packages/airflow/models/taskinstance.py", line 1543, in signal_handler
    raise AirflowException("Task received SIGTERM signal")
airflow.exceptions.AirflowException: Task received SIGTERM signal
[2025-08-06 10:40:19,834] {taskinstance.py:1400} INFO - Marking task as FAILED. dag_id=send_weather_to_kafka, task_id=run_kafka_consumer_to_redis, execution_date=20250806T080000, start_date=20250806T090006, end_date=20250806T104019
[2025-08-06 10:40:19,853] {standard_task_runner.py:97} ERROR - Failed to execute job 12 for task run_kafka_consumer_to_redis (Task received SIGTERM signal; 21191)
[2025-08-06 10:40:19,893] {process_utils.py:75} INFO - Process psutil.Process(pid=21192, status='terminated', started='09:00:06') (21192) terminated with exit code None
[2025-08-06 10:40:19,894] {process_utils.py:75} INFO - Process psutil.Process(pid=21191, status='terminated', exitcode=1, started='09:00:06') (21191) terminated with exit code 1
