[2025-08-06 08:12:37,172] {taskinstance.py:1159} INFO - Dependencies all met for <TaskInstance: send_weather_to_kafka.run_kafka_consumer_to_redis scheduled__2025-08-05T23:00:00+00:00 [queued]>
[2025-08-06 08:12:37,188] {taskinstance.py:1159} INFO - Dependencies all met for <TaskInstance: send_weather_to_kafka.run_kafka_consumer_to_redis scheduled__2025-08-05T23:00:00+00:00 [queued]>
[2025-08-06 08:12:37,188] {taskinstance.py:1356} INFO - 
--------------------------------------------------------------------------------
[2025-08-06 08:12:37,188] {taskinstance.py:1357} INFO - Starting attempt 1 of 2
[2025-08-06 08:12:37,188] {taskinstance.py:1358} INFO - 
--------------------------------------------------------------------------------
[2025-08-06 08:12:37,211] {taskinstance.py:1377} INFO - Executing <Task(BashOperator): run_kafka_consumer_to_redis> on 2025-08-05 23:00:00+00:00
[2025-08-06 08:12:37,218] {standard_task_runner.py:52} INFO - Started process 20706 to run task
[2025-08-06 08:12:37,223] {standard_task_runner.py:79} INFO - Running: ['***', 'tasks', 'run', 'send_weather_to_kafka', 'run_kafka_consumer_to_redis', 'scheduled__2025-08-05T23:00:00+00:00', '--job-id', '9', '--raw', '--subdir', 'DAGS_FOLDER/dag_meteo.py', '--cfg-path', '/tmp/tmpi5z_0ayp', '--error-file', '/tmp/tmpz80a9kha']
[2025-08-06 08:12:37,225] {standard_task_runner.py:80} INFO - Job 9: Subtask run_kafka_consumer_to_redis
[2025-08-06 08:12:37,250] {logging_mixin.py:115} WARNING - /home/***/.local/lib/python3.7/site-packages/***/configuration.py:470 DeprecationWarning: The sql_alchemy_conn option in [core] has been moved to the sql_alchemy_conn option in [database] - the old setting has been used, but please update your config.
[2025-08-06 08:12:37,313] {task_command.py:369} INFO - Running <TaskInstance: send_weather_to_kafka.run_kafka_consumer_to_redis scheduled__2025-08-05T23:00:00+00:00 [running]> on host 536c12e0b7f9
[2025-08-06 08:12:37,436] {taskinstance.py:1571} INFO - Exporting the following env vars:
AIRFLOW_CTX_DAG_OWNER=***
AIRFLOW_CTX_DAG_ID=send_weather_to_kafka
AIRFLOW_CTX_TASK_ID=run_kafka_consumer_to_redis
AIRFLOW_CTX_EXECUTION_DATE=2025-08-05T23:00:00+00:00
AIRFLOW_CTX_TRY_NUMBER=1
AIRFLOW_CTX_DAG_RUN_ID=scheduled__2025-08-05T23:00:00+00:00
[2025-08-06 08:12:37,438] {subprocess.py:62} INFO - Tmp dir root location: 
 /tmp
[2025-08-06 08:12:37,439] {subprocess.py:74} INFO - Running command: ['bash', '-c', 'cd /opt/***/scripts && python3 kafka/consumer_redis.py']
[2025-08-06 08:12:37,461] {subprocess.py:85} INFO - Output:
[2025-08-06 10:40:19,343] {local_task_job.py:221} WARNING - State of this instance has been externally set to removed. Terminating instance.
[2025-08-06 10:40:19,357] {process_utils.py:129} INFO - Sending Signals.SIGTERM to group 20706. PIDs of all processes in the group: [20708, 20706]
[2025-08-06 10:40:19,359] {process_utils.py:80} INFO - Sending the signal Signals.SIGTERM to group 20706
[2025-08-06 10:40:19,372] {taskinstance.py:1541} ERROR - Received SIGTERM. Terminating subprocesses.
[2025-08-06 10:40:19,388] {subprocess.py:103} INFO - Sending SIGTERM signal to process group
[2025-08-06 10:40:19,608] {taskinstance.py:1889} ERROR - Task failed with exception
Traceback (most recent call last):
  File "/home/airflow/.local/lib/python3.7/site-packages/airflow/operators/bash.py", line 189, in execute
    cwd=self.cwd,
  File "/home/airflow/.local/lib/python3.7/site-packages/airflow/hooks/subprocess.py", line 90, in run_command
    for raw_line in iter(self.sub_process.stdout.readline, b''):
  File "/home/airflow/.local/lib/python3.7/site-packages/airflow/models/taskinstance.py", line 1543, in signal_handler
    raise AirflowException("Task received SIGTERM signal")
airflow.exceptions.AirflowException: Task received SIGTERM signal
[2025-08-06 10:40:19,634] {taskinstance.py:1400} INFO - Marking task as FAILED. dag_id=send_weather_to_kafka, task_id=run_kafka_consumer_to_redis, execution_date=20250805T230000, start_date=20250806T081237, end_date=20250806T104019
[2025-08-06 10:40:19,691] {standard_task_runner.py:97} ERROR - Failed to execute job 9 for task run_kafka_consumer_to_redis (Task received SIGTERM signal; 20706)
[2025-08-06 10:40:19,734] {process_utils.py:75} INFO - Process psutil.Process(pid=20708, status='terminated', started='08:12:36') (20708) terminated with exit code None
[2025-08-06 10:40:19,736] {process_utils.py:75} INFO - Process psutil.Process(pid=20706, status='terminated', exitcode=1, started='08:12:36') (20706) terminated with exit code 1
