[2025-08-06 10:58:16,113] {taskinstance.py:1159} INFO - Dependencies all met for <TaskInstance: send_weather_to_kafka.run_kafka_consumer_to_logstash manual__2025-08-06T10:58:08.647619+00:00 [queued]>
[2025-08-06 10:58:16,127] {taskinstance.py:1159} INFO - Dependencies all met for <TaskInstance: send_weather_to_kafka.run_kafka_consumer_to_logstash manual__2025-08-06T10:58:08.647619+00:00 [queued]>
[2025-08-06 10:58:16,127] {taskinstance.py:1356} INFO - 
--------------------------------------------------------------------------------
[2025-08-06 10:58:16,127] {taskinstance.py:1357} INFO - Starting attempt 1 of 2
[2025-08-06 10:58:16,127] {taskinstance.py:1358} INFO - 
--------------------------------------------------------------------------------
[2025-08-06 10:58:16,145] {taskinstance.py:1377} INFO - Executing <Task(BashOperator): run_kafka_consumer_to_logstash> on 2025-08-06 10:58:08.647619+00:00
[2025-08-06 10:58:16,151] {standard_task_runner.py:52} INFO - Started process 22594 to run task
[2025-08-06 10:58:16,155] {standard_task_runner.py:79} INFO - Running: ['***', 'tasks', 'run', 'send_weather_to_kafka', 'run_kafka_consumer_to_logstash', 'manual__2025-08-06T10:58:08.647619+00:00', '--job-id', '24', '--raw', '--subdir', 'DAGS_FOLDER/dag_meteo.py', '--cfg-path', '/tmp/tmpl8jtvadv', '--error-file', '/tmp/tmpgbzu66p9']
[2025-08-06 10:58:16,157] {standard_task_runner.py:80} INFO - Job 24: Subtask run_kafka_consumer_to_logstash
[2025-08-06 10:58:16,232] {task_command.py:369} INFO - Running <TaskInstance: send_weather_to_kafka.run_kafka_consumer_to_logstash manual__2025-08-06T10:58:08.647619+00:00 [running]> on host 536c12e0b7f9
[2025-08-06 10:58:16,343] {taskinstance.py:1571} INFO - Exporting the following env vars:
AIRFLOW_CTX_DAG_OWNER=***
AIRFLOW_CTX_DAG_ID=send_weather_to_kafka
AIRFLOW_CTX_TASK_ID=run_kafka_consumer_to_logstash
AIRFLOW_CTX_EXECUTION_DATE=2025-08-06T10:58:08.647619+00:00
AIRFLOW_CTX_TRY_NUMBER=1
AIRFLOW_CTX_DAG_RUN_ID=manual__2025-08-06T10:58:08.647619+00:00
[2025-08-06 10:58:16,344] {subprocess.py:62} INFO - Tmp dir root location: 
 /tmp
[2025-08-06 10:58:16,344] {subprocess.py:74} INFO - Running command: ['bash', '-c', '/usr/share/logstash/bin/logstash -f /usr/share/logstash/pipeline/logstash.conf']
[2025-08-06 10:58:16,359] {subprocess.py:85} INFO - Output:
[2025-08-06 10:58:16,363] {subprocess.py:92} INFO - bash: line 1: /usr/share/logstash/bin/logstash: No such file or directory
[2025-08-06 10:58:16,363] {subprocess.py:96} INFO - Command exited with return code 127
[2025-08-06 10:58:16,386] {taskinstance.py:1889} ERROR - Task failed with exception
Traceback (most recent call last):
  File "/home/airflow/.local/lib/python3.7/site-packages/airflow/operators/bash.py", line 195, in execute
    f'Bash command failed. The command returned a non-zero exit code {result.exit_code}.'
airflow.exceptions.AirflowException: Bash command failed. The command returned a non-zero exit code 127.
[2025-08-06 10:58:16,392] {taskinstance.py:1400} INFO - Marking task as UP_FOR_RETRY. dag_id=send_weather_to_kafka, task_id=run_kafka_consumer_to_logstash, execution_date=20250806T105808, start_date=20250806T105816, end_date=20250806T105816
[2025-08-06 10:58:16,407] {standard_task_runner.py:97} ERROR - Failed to execute job 24 for task run_kafka_consumer_to_logstash (Bash command failed. The command returned a non-zero exit code 127.; 22594)
[2025-08-06 10:58:16,447] {local_task_job.py:156} INFO - Task exited with return code 1
[2025-08-06 10:58:16,500] {local_task_job.py:273} INFO - 0 downstream tasks scheduled from follow-on schedule check
