[2025-08-07 11:23:49,153] {taskinstance.py:1159} INFO - Dependencies all met for <TaskInstance: send_weather_to_kafka.verify_pipeline scheduled__2025-08-07T11:21:41.830671+00:00 [queued]>
[2025-08-07 11:23:49,166] {taskinstance.py:1159} INFO - Dependencies all met for <TaskInstance: send_weather_to_kafka.verify_pipeline scheduled__2025-08-07T11:21:41.830671+00:00 [queued]>
[2025-08-07 11:23:49,166] {taskinstance.py:1356} INFO - 
--------------------------------------------------------------------------------
[2025-08-07 11:23:49,166] {taskinstance.py:1357} INFO - Starting attempt 1 of 2
[2025-08-07 11:23:49,166] {taskinstance.py:1358} INFO - 
--------------------------------------------------------------------------------
[2025-08-07 11:23:49,185] {taskinstance.py:1377} INFO - Executing <Task(BashOperator): verify_pipeline> on 2025-08-07 11:21:41.830671+00:00
[2025-08-07 11:23:49,191] {standard_task_runner.py:52} INFO - Started process 6543 to run task
[2025-08-07 11:23:49,194] {standard_task_runner.py:79} INFO - Running: ['***', 'tasks', 'run', 'send_weather_to_kafka', 'verify_pipeline', 'scheduled__2025-08-07T11:21:41.830671+00:00', '--job-id', '130', '--raw', '--subdir', 'DAGS_FOLDER/dag_meteo.py', '--cfg-path', '/tmp/tmpykjohdfn', '--error-file', '/tmp/tmp6dx9190s']
[2025-08-07 11:23:49,196] {standard_task_runner.py:80} INFO - Job 130: Subtask verify_pipeline
[2025-08-07 11:23:49,283] {task_command.py:369} INFO - Running <TaskInstance: send_weather_to_kafka.verify_pipeline scheduled__2025-08-07T11:21:41.830671+00:00 [running]> on host b22dcc1493a4
[2025-08-07 11:23:49,557] {taskinstance.py:1571} INFO - Exporting the following env vars:
AIRFLOW_CTX_DAG_OWNER=alla
AIRFLOW_CTX_DAG_ID=send_weather_to_kafka
AIRFLOW_CTX_TASK_ID=verify_pipeline
AIRFLOW_CTX_EXECUTION_DATE=2025-08-07T11:21:41.830671+00:00
AIRFLOW_CTX_TRY_NUMBER=1
AIRFLOW_CTX_DAG_RUN_ID=scheduled__2025-08-07T11:21:41.830671+00:00
[2025-08-07 11:23:49,558] {subprocess.py:62} INFO - Tmp dir root location: 
 /tmp
[2025-08-07 11:23:49,559] {subprocess.py:74} INFO - Running command: ['bash', '-c', '\n            echo " Attente traitement Logstash..." && sleep 30 &&\n            curl -s "http://elasticsearch:9200/_cat/indices/weather*" || echo "Pas encore d\'index weather"\n        ']
[2025-08-07 11:23:49,575] {subprocess.py:85} INFO - Output:
[2025-08-07 11:23:49,578] {subprocess.py:92} INFO -  Attente traitement Logstash...
[2025-08-07 11:23:51,230] {local_task_job.py:84} ERROR - Received SIGTERM. Terminating subprocesses
[2025-08-07 11:23:51,256] {process_utils.py:129} INFO - Sending Signals.SIGTERM to group 6543. PIDs of all processes in the group: [6544, 6545, 6543]
[2025-08-07 11:23:51,257] {process_utils.py:80} INFO - Sending the signal Signals.SIGTERM to group 6543
[2025-08-07 11:23:51,258] {taskinstance.py:1541} ERROR - Received SIGTERM. Terminating subprocesses.
[2025-08-07 11:23:51,259] {subprocess.py:103} INFO - Sending SIGTERM signal to process group
[2025-08-07 11:23:51,306] {taskinstance.py:1889} ERROR - Task failed with exception
Traceback (most recent call last):
  File "/home/airflow/.local/lib/python3.7/site-packages/airflow/operators/bash.py", line 189, in execute
    cwd=self.cwd,
  File "/home/airflow/.local/lib/python3.7/site-packages/airflow/hooks/subprocess.py", line 90, in run_command
    for raw_line in iter(self.sub_process.stdout.readline, b''):
  File "/home/airflow/.local/lib/python3.7/site-packages/airflow/models/taskinstance.py", line 1543, in signal_handler
    raise AirflowException("Task received SIGTERM signal")
airflow.exceptions.AirflowException: Task received SIGTERM signal
[2025-08-07 11:23:51,343] {taskinstance.py:1400} INFO - Marking task as UP_FOR_RETRY. dag_id=send_weather_to_kafka, task_id=verify_pipeline, execution_date=20250807T112141, start_date=20250807T112349, end_date=20250807T112351
[2025-08-07 11:23:51,418] {standard_task_runner.py:97} ERROR - Failed to execute job 130 for task verify_pipeline (Task received SIGTERM signal; 6543)
[2025-08-07 11:23:51,474] {process_utils.py:75} INFO - Process psutil.Process(pid=6543, status='terminated', exitcode=1, started='11:23:48') (6543) terminated with exit code 1
[2025-08-07 11:23:51,475] {process_utils.py:75} INFO - Process psutil.Process(pid=6545, status='terminated', started='11:23:49') (6545) terminated with exit code None
[2025-08-07 11:23:51,475] {process_utils.py:75} INFO - Process psutil.Process(pid=6544, status='terminated', started='11:23:49') (6544) terminated with exit code None
[2025-08-07 11:23:51,476] {local_task_job.py:156} INFO - Task exited with return code 143
[2025-08-07 11:23:51,537] {local_task_job.py:273} INFO - 0 downstream tasks scheduled from follow-on schedule check
[2025-08-07 11:23:53,442] {local_task_job.py:84} ERROR - Received SIGTERM. Terminating subprocesses
[2025-08-07 11:23:53,442] {local_task_job.py:156} INFO - Task exited with return code 143
